<?xml version="1.0" ?>
<!-- =================================================================================== -->
<!-- |    This document was autogenerated by xacro from underwater_snakerobot.urdf.xacro | -->
<!-- |    EDITING THIS FILE BY HAND IS NOT RECOMMENDED                                 | -->
<!-- =================================================================================== -->
<!--
  Base xacro for the Amphibious Snake-like Robot.
  Converted from the legacy package to use package:// URLs so meshes load
  correctly from install space in ROS 2.
-->
<robot name="underwater_snakerobot_description">
  <!---............................. Link Definitions ................................-->
  <link name="world">
  </link>
  <link name="base_link">
    <inertial>
      <mass value="4"/>
      <inertia ixx="0.2" ixy="0" ixz="0" iyy="0.2" iyz="0" izz="0.2"/>
    </inertial>
    <visual>
      <origin rpy="3.141592653589793 0 -1.5707963267948966" xyz="0.0 0.0 0.0"/>
      <geometry>
        <!-- RViz2(Jazzy) 对 .osg 支持不佳，这里改用已有的 Collada 网格 -->
        <mesh filename="package://asr_sdm_description/meshes/body_2links.dae"/>
      </geometry>
    </visual>
  </link>
  <link name="screw_1_left">
    <inertial>
      <mass value="0.5"/>
      <inertia ixx="0.01" ixy="0" ixz="0" iyy="0.01" iyz="0" izz="0.01"/>
    </inertial>
    <visual>
      <origin rpy="0 4.71238898038469 0" xyz="0.0 0.0 0.0"/>
      <geometry>
        <!-- 使用仓库中已有且 RViz 支持良好的 Collada 网格 -->
        <mesh filename="package://asr_sdm_description/meshes/screw_left_CFD.dae"/>
      </geometry>
    </visual>
  </link>
  <link name="screw_1_right">
    <inertial>
      <mass value="0.5"/>
      <inertia ixx="0.01" ixy="0" ixz="0" iyy="0.01" iyz="0" izz="0.01"/>
    </inertial>
    <visual>
      <origin rpy="0 1.5707963267948966 0" xyz="-0.0 0.0 0.0"/>
      <geometry>
        <mesh filename="package://asr_sdm_description/meshes/screw_right_CFD.dae"/>
      </geometry>
    </visual>
  </link>
  <link name="link_2">
    <inertial>
      <mass value="4"/>
      <inertia ixx="0.2" ixy="0" ixz="0" iyy="0.2" iyz="0" izz="0.2"/>
    </inertial>
    <visual>
      <origin rpy="0 0 0" xyz="0.0 0.0 0.0"/>
      <geometry>
        <mesh filename="package://asr_sdm_description/meshes/body_2links.dae"/>
      </geometry>
    </visual>
  </link>
  <link name="screw_2_left">
    <inertial>
      <mass value="0.5"/>
      <inertia ixx="0.01" ixy="0" ixz="0" iyy="0.01" iyz="0" izz="0.01"/>
    </inertial>
    <visual>
      <origin rpy="0 4.71238898038469 0" xyz="0.0 0.0 0.0"/>
      <geometry>
        <mesh filename="package://asr_sdm_description/meshes/screw_left_CFD.dae"/>
      </geometry>
    </visual>
  </link>
  <link name="screw_2_right">
    <inertial>
      <mass value="0.5"/>
      <inertia ixx="0.01" ixy="0" ixz="0" iyy="0.01" iyz="0" izz="0.01"/>
    </inertial>
    <visual>
      <origin rpy="0 -1.5707963267948966 0" xyz="-0.0 0.0 0.0"/>
      <geometry>
        <mesh filename="package://asr_sdm_description/meshes/screw_right_CFD.dae"/>
      </geometry>
    </visual>
  </link>
  <joint name="base_link_to_link_2" type="continuous">
    <parent link="base_link"/>
    <child link="link_2"/>
    <origin rpy="0 0 0" xyz="0 0 0.18"/>
    <limit effort="100.0" lower="-1.0" upper="1.0" velocity="10.0"/>
    <safety_controller k_position="20" k_velocity="20"/>
  </joint>
  <joint name="link_2_to_screw_2_left_joint" type="continuous">
    <parent link="link_2"/>
    <child link="screw_2_left"/>
    <origin rpy="0 4.71238898038469 0" xyz="0 0 0.117"/>
    <limit effort="1000.0" lower="-3.14159" upper="3.14159" velocity="10.0"/>
    <safety_controller k_position="5" k_velocity="5"/>
  </joint>
  <joint name="link_2_to_screw_2_right_joint" type="continuous">
    <parent link="link_2"/>
    <child link="screw_2_right"/>
    <origin rpy="0 1.5707963267948966 0" xyz="0 0 0.181"/>
    <limit effort="1000.0" lower="-3.14159" upper="3.14159" velocity="10.0"/>
    <safety_controller k_position="5" k_velocity="5"/>
  </joint>
  <link name="link_3">
    <inertial>
      <mass value="4"/>
      <inertia ixx="0.2" ixy="0" ixz="0" iyy="0.2" iyz="0" izz="0.2"/>
    </inertial>
    <visual>
      <origin rpy="0 0 0" xyz="0.0 0.0 0.0"/>
      <geometry>
        <mesh filename="package://asr_sdm_description/meshes/body_2links.dae"/>
      </geometry>
    </visual>
  </link>
  <link name="screw_3_left">
    <inertial>
      <mass value="0.5"/>
      <inertia ixx="0.01" ixy="0" ixz="0" iyy="0.01" iyz="0" izz="0.01"/>
    </inertial>
    <visual>
      <origin rpy="0 4.71238898038469 0" xyz="0.0 0.0 0.0"/>
      <geometry>
        <mesh filename="package://asr_sdm_description/meshes/screw_left_CFD.dae"/>
      </geometry>
    </visual>
  </link>
  <link name="screw_3_right">
    <inertial>
      <mass value="0.5"/>
      <inertia ixx="0.01" ixy="0" ixz="0" iyy="0.01" iyz="0" izz="0.01"/>
    </inertial>
    <visual>
      <origin rpy="0 -1.5707963267948966 0" xyz="-0.0 0.0 0.0"/>
      <geometry>
        <mesh filename="package://asr_sdm_description/meshes/screw_right_CFD.dae"/>
      </geometry>
    </visual>
  </link>
  <joint name="link_2_to_link_3" type="continuous">
    <parent link="link_2"/>
    <child link="link_3"/>
    <origin rpy="0 0 0" xyz="0 0 0.18"/>
    <limit effort="100.0" lower="-1.0" upper="1.0" velocity="10.0"/>
    <safety_controller k_position="20" k_velocity="20"/>
  </joint>
  <joint name="link_3_to_screw_3_left_joint" type="continuous">
    <parent link="link_3"/>
    <child link="screw_3_left"/>
    <origin rpy="0 4.71238898038469 0" xyz="0 0 0.117"/>
    <limit effort="1000.0" lower="-3.14159" upper="3.14159" velocity="10.0"/>
    <safety_controller k_position="5" k_velocity="5"/>
  </joint>
  <joint name="link_3_to_screw_3_right_joint" type="continuous">
    <parent link="link_3"/>
    <child link="screw_3_right"/>
    <origin rpy="0 1.5707963267948966 0" xyz="0 0 0.181"/>
    <limit effort="1000.0" lower="-3.14159" upper="3.14159" velocity="10.0"/>
    <safety_controller k_position="5" k_velocity="5"/>
  </joint>
  <link name="link_4">
    <inertial>
      <mass value="4"/>
      <inertia ixx="0.2" ixy="0" ixz="0" iyy="0.2" iyz="0" izz="0.2"/>
    </inertial>
    <visual>
      <origin rpy="0 0 0" xyz="0.0 0.0 0.0"/>
      <geometry>
        <mesh filename="package://asr_sdm_description/meshes/body_2links.dae"/>
      </geometry>
    </visual>
  </link>
  <link name="screw_4_left">
    <inertial>
      <mass value="0.5"/>
      <inertia ixx="0.01" ixy="0" ixz="0" iyy="0.01" iyz="0" izz="0.01"/>
    </inertial>
    <visual>
      <origin rpy="0 4.71238898038469 0" xyz="0.0 0.0 0.0"/>
      <geometry>
        <mesh filename="package://asr_sdm_description/meshes/screw_left_CFD.dae"/>
      </geometry>
    </visual>
  </link>
  <link name="screw_4_right">
    <inertial>
      <mass value="0.5"/>
      <inertia ixx="0.01" ixy="0" ixz="0" iyy="0.01" iyz="0" izz="0.01"/>
    </inertial>
    <visual>
      <origin rpy="0 -1.5707963267948966 0" xyz="-0.0 0.0 0.0"/>
      <geometry>
        <mesh filename="package://asr_sdm_description/meshes/screw_right_CFD.dae"/>
      </geometry>
    </visual>
  </link>
  <joint name="link_3_to_link_4" type="continuous">
    <parent link="link_3"/>
    <child link="link_4"/>
    <origin rpy="0 0 0" xyz="0 0 0.18"/>
    <limit effort="100.0" lower="-1.0" upper="1.0" velocity="10.0"/>
    <safety_controller k_position="20" k_velocity="20"/>
  </joint>
  <joint name="link_4_to_screw_4_left_joint" type="continuous">
    <parent link="link_4"/>
    <child link="screw_4_left"/>
    <origin rpy="0 4.71238898038469 0" xyz="0 0 0.117"/>
    <limit effort="1000.0" lower="-3.14159" upper="3.14159" velocity="10.0"/>
    <safety_controller k_position="5" k_velocity="5"/>
  </joint>
  <joint name="link_4_to_screw_4_right_joint" type="continuous">
    <parent link="link_4"/>
    <child link="screw_4_right"/>
    <origin rpy="0 1.5707963267948966 0" xyz="0 0 0.181"/>
    <limit effort="1000.0" lower="-3.14159" upper="3.14159" velocity="10.0"/>
    <safety_controller k_position="5" k_velocity="5"/>
  </joint>
  <link name="link_5">
    <inertial>
      <mass value="4"/>
      <inertia ixx="0.2" ixy="0" ixz="0" iyy="0.2" iyz="0" izz="0.2"/>
    </inertial>
    <visual>
      <origin rpy="0 0 0" xyz="0.0 0.0 0.0"/>
      <geometry>
        <mesh filename="package://asr_sdm_description/meshes/body_2links.dae"/>
      </geometry>
    </visual>
  </link>
  <link name="screw_5_left">
    <inertial>
      <mass value="0.5"/>
      <inertia ixx="0.01" ixy="0" ixz="0" iyy="0.01" iyz="0" izz="0.01"/>
    </inertial>
    <visual>
      <origin rpy="0 4.71238898038469 0" xyz="0.0 0.0 0.0"/>
      <geometry>
        <mesh filename="package://asr_sdm_description/meshes/screw_left_CFD.dae"/>
      </geometry>
    </visual>
  </link>
  <link name="screw_5_right">
    <inertial>
      <mass value="0.5"/>
      <inertia ixx="0.01" ixy="0" ixz="0" iyy="0.01" iyz="0" izz="0.01"/>
    </inertial>
    <visual>
      <origin rpy="0 -1.5707963267948966 0" xyz="-0.0 0.0 0.0"/>
      <geometry>
        <mesh filename="package://asr_sdm_description/meshes/screw_right_CFD.dae"/>
      </geometry>
    </visual>
  </link>
  <joint name="link_4_to_link_5" type="continuous">
    <parent link="link_4"/>
    <child link="link_5"/>
    <origin rpy="0 0 0" xyz="0 0 0.18"/>
    <limit effort="100.0" lower="-1.0" upper="1.0" velocity="10.0"/>
    <safety_controller k_position="20" k_velocity="20"/>
  </joint>
  <joint name="link_5_to_screw_5_left_joint" type="continuous">
    <parent link="link_5"/>
    <child link="screw_5_left"/>
    <origin rpy="0 4.71238898038469 0" xyz="0 0 0.117"/>
    <limit effort="1000.0" lower="-3.14159" upper="3.14159" velocity="10.0"/>
    <safety_controller k_position="5" k_velocity="5"/>
  </joint>
  <joint name="link_5_to_screw_5_right_joint" type="continuous">
    <parent link="link_5"/>
    <child link="screw_5_right"/>
    <origin rpy="0 1.5707963267948966 0" xyz="0 0 0.181"/>
    <limit effort="1000.0" lower="-3.14159" upper="3.14159" velocity="10.0"/>
    <safety_controller k_position="5" k_velocity="5"/>
  </joint>
  <!--...........................Base joints............................................-->
  <joint name="world_to_base_link" type="fixed">
    <parent link="world"/>
    <child link="base_link"/>
    <origin rpy="0 0 0" xyz="0 0 0"/>
  </joint>
  <joint name="base_link_to_screw_1_left_joint" type="continuous">
    <parent link="base_link"/>
    <child link="screw_1_left"/>
    <origin rpy="0 4.71238898038469 0" xyz="0 0 0.117"/>
    <limit effort="1000.0" lower="-3.14159" upper="3.14159" velocity="10.0"/>
    <safety_controller k_position="5" k_velocity="5"/>
  </joint>
  <joint name="base_link_to_screw_1_right_joint" type="continuous">
    <parent link="base_link"/>
    <child link="screw_1_right"/>
    <origin rpy="0 1.5707963267948966 0" xyz="0 0 0.181"/>
    <limit effort="1000.0" lower="-3.14159" upper="3.14159" velocity="10.0"/>
    <safety_controller k_position="5" k_velocity="5"/>
  </joint>
</robot>
